[05/May/2016 14:38:39] ERROR [django.request:284] Internal Server Error: /resta/api/restaurante/angular
Traceback (most recent call last):
  File "/Library/Python/2.7/site-packages/django/core/handlers/base.py", line 235, in get_response
    response = middleware_method(request, response)
  File "/Library/Python/2.7/site-packages/django/middleware/common.py", line 115, in process_response
    return self.response_redirect_class(self.get_full_path_with_slash(request))
  File "/Library/Python/2.7/site-packages/django/middleware/common.py", line 99, in get_full_path_with_slash
    'url': request.get_host() + new_path,
RuntimeError: You called this URL via PUT, but the URL doesn't end in a slash and you have APPEND_SLASH set. Django can't redirect to the slash URL while maintaining PUT data. Change your form to point to localhost:8000/resta/api/restaurante/angular/ (note the trailing slash), or set APPEND_SLASH=False in your Django settings.
[05/May/2016 14:41:08] ERROR [django.request:284] Internal Server Error: /resta/api/restaurante/1111holaahhhha
Traceback (most recent call last):
  File "/Library/Python/2.7/site-packages/django/core/handlers/base.py", line 235, in get_response
    response = middleware_method(request, response)
  File "/Library/Python/2.7/site-packages/django/middleware/common.py", line 115, in process_response
    return self.response_redirect_class(self.get_full_path_with_slash(request))
  File "/Library/Python/2.7/site-packages/django/middleware/common.py", line 99, in get_full_path_with_slash
    'url': request.get_host() + new_path,
RuntimeError: You called this URL via PUT, but the URL doesn't end in a slash and you have APPEND_SLASH set. Django can't redirect to the slash URL while maintaining PUT data. Change your form to point to localhost:8000/resta/api/restaurante/1111holaahhhha/ (note the trailing slash), or set APPEND_SLASH=False in your Django settings.
[05/May/2016 14:43:52] ERROR [django.request:284] Internal Server Error: /resta/api/restaurante/pruebaxd/
Traceback (most recent call last):
  File "/Library/Python/2.7/site-packages/django/core/handlers/base.py", line 149, in get_response
    response = self.process_exception_by_middleware(e, request)
  File "/Library/Python/2.7/site-packages/django/core/handlers/base.py", line 147, in get_response
    response = wrapped_callback(request, *callback_args, **callback_kwargs)
  File "/Library/Python/2.7/site-packages/django/views/decorators/csrf.py", line 58, in wrapped_view
    return view_func(*args, **kwargs)
  File "/Library/Python/2.7/site-packages/django/views/generic/base.py", line 68, in view
    return self.dispatch(request, *args, **kwargs)
  File "/Library/Python/2.7/site-packages/rest_framework/views.py", line 466, in dispatch
    response = self.handle_exception(exc)
  File "/Library/Python/2.7/site-packages/rest_framework/views.py", line 463, in dispatch
    response = handler(request, *args, **kwargs)
  File "/Library/Python/2.7/site-packages/rest_framework/decorators.py", line 53, in handler
    return func(*args, **kwargs)
  File "/Library/Python/2.7/site-packages/django/views/decorators/csrf.py", line 58, in wrapped_view
    return view_func(*args, **kwargs)
  File "/Users/alberto/Desktop/Universidad/Master/2 Cuatrimestre/SSIW/Practicas/WebRestaurantes/restaurantes/Restaurantes/app_restaurantes/views.py", line 224, in api_restaurante
    restaurante.email = jsonRequest["email"]
KeyError: 'email'
[05/May/2016 14:43:58] ERROR [django.request:284] Internal Server Error: /resta/api/restaurante/pruebaxd/
Traceback (most recent call last):
  File "/Library/Python/2.7/site-packages/django/core/handlers/base.py", line 149, in get_response
    response = self.process_exception_by_middleware(e, request)
  File "/Library/Python/2.7/site-packages/django/core/handlers/base.py", line 147, in get_response
    response = wrapped_callback(request, *callback_args, **callback_kwargs)
  File "/Library/Python/2.7/site-packages/django/views/decorators/csrf.py", line 58, in wrapped_view
    return view_func(*args, **kwargs)
  File "/Library/Python/2.7/site-packages/django/views/generic/base.py", line 68, in view
    return self.dispatch(request, *args, **kwargs)
  File "/Library/Python/2.7/site-packages/rest_framework/views.py", line 466, in dispatch
    response = self.handle_exception(exc)
  File "/Library/Python/2.7/site-packages/rest_framework/views.py", line 463, in dispatch
    response = handler(request, *args, **kwargs)
  File "/Library/Python/2.7/site-packages/rest_framework/decorators.py", line 53, in handler
    return func(*args, **kwargs)
  File "/Library/Python/2.7/site-packages/django/views/decorators/csrf.py", line 58, in wrapped_view
    return view_func(*args, **kwargs)
  File "/Users/alberto/Desktop/Universidad/Master/2 Cuatrimestre/SSIW/Practicas/WebRestaurantes/restaurantes/Restaurantes/app_restaurantes/views.py", line 224, in api_restaurante
    restaurante.email = jsonRequest["email"]
KeyError: 'email'
[05/May/2016 14:45:49] ERROR [Views.py:193] {'nombre': [u'Ya existe Restaurante con este nombre.'], 'email': [u'Este campo es requerido.']}
[05/May/2016 14:49:02] ERROR [Views.py:193] {'nombre': [u'Ya existe Restaurante con este nombre.']}
[05/May/2016 14:49:07] ERROR [Views.py:193] {'nombre': [u'Ya existe Restaurante con este nombre.']}
[05/May/2016 14:49:10] ERROR [Views.py:193] {'nombre': [u'Ya existe Restaurante con este nombre.']}
[05/May/2016 14:59:07] ERROR [Views.py:193] {'nombre': [u'Ya existe Restaurante con este nombre.']}
[05/May/2016 15:19:57] ERROR [Views.py:193] {'email': [u'Introduzca una direcci\xf3n de correo electr\xf3nico v\xe1lida.']}
[05/May/2016 15:20:00] ERROR [Views.py:193] {'email': [u'Introduzca una direcci\xf3n de correo electr\xf3nico v\xe1lida.']}
[05/May/2016 15:28:17] ERROR [Views.py:193] {'nombre': [u'Ya existe Restaurante con este nombre.']}
[05/May/2016 15:28:21] ERROR [Views.py:193] {'nombre': [u'Ya existe Restaurante con este nombre.']}
